============================= test session starts ==============================
platform darwin -- Python 3.13.7, pytest-8.4.2, pluggy-1.6.0 -- /Users/frisowempe/ISA_D/.venv/bin/python3
cachedir: .pytest_cache
metadata: {'Python': '3.13.7', 'Platform': 'macOS-15.6-arm64-arm-64bit-Mach-O', 'Packages': {'pytest': '8.4.2', 'pluggy': '1.6.0'}, 'Plugins': {'html': '4.1.1', 'asyncio': '1.1.0', 'xdist': '3.8.0', 'mock': '3.15.0', 'timeout': '2.4.0', 'langsmith': '0.4.28', 'metadata': '3.1.1', 'anyio': '4.10.0', 'cov': '6.2.1'}}
rootdir: /Users/frisowempe/ISA_D
configfile: pytest.ini
plugins: html-4.1.1, asyncio-1.1.0, xdist-3.8.0, mock-3.15.0, timeout-2.4.0, langsmith-0.4.28, metadata-3.1.1, anyio-4.10.0, cov-6.2.1
asyncio: mode=Mode.STRICT, asyncio_default_fixture_loop_scope=None, asyncio_default_test_loop_scope=function
collecting ... collected 71 items / 15 errors

==================================== ERRORS ====================================
____________________ ERROR collecting tests/test_agents.py _____________________
ImportError while importing test module '/Users/frisowempe/ISA_D/tests/test_agents.py'.
Hint: make sure your test modules/packages have valid Python names.
Traceback:
/opt/homebrew/Cellar/python@3.13/3.13.7/Frameworks/Python.framework/Versions/3.13/lib/python3.13/importlib/__init__.py:88: in import_module
    return _bootstrap._gcd_import(name[level:], package, level)
           ^^^^^^^^^^^^^^^^^^^^^^^^^^^^^^^^^^^^^^^^^^^^^^^^^^^^
tests/test_agents.py:12: in <module>
    from isa_superapp.agents.base import AgentResponse, AgentState, BaseAgent
E   ModuleNotFoundError: No module named 'isa_superapp'
_____________________ ERROR collecting tests/test_core.py ______________________
ImportError while importing test module '/Users/frisowempe/ISA_D/tests/test_core.py'.
Hint: make sure your test modules/packages have valid Python names.
Traceback:
/opt/homebrew/Cellar/python@3.13/3.13.7/Frameworks/Python.framework/Versions/3.13/lib/python3.13/importlib/__init__.py:88: in import_module
    return _bootstrap._gcd_import(name[level:], package, level)
           ^^^^^^^^^^^^^^^^^^^^^^^^^^^^^^^^^^^^^^^^^^^^^^^^^^^^
tests/test_core.py:13: in <module>
    from isa_superapp.core.config import Config, ConfigManager, ConfigurationError
E   ModuleNotFoundError: No module named 'isa_superapp'
___________________ ERROR collecting tests/test_core_app.py ____________________
ImportError while importing test module '/Users/frisowempe/ISA_D/tests/test_core_app.py'.
Hint: make sure your test modules/packages have valid Python names.
Traceback:
/opt/homebrew/Cellar/python@3.13/3.13.7/Frameworks/Python.framework/Versions/3.13/lib/python3.13/importlib/__init__.py:88: in import_module
    return _bootstrap._gcd_import(name[level:], package, level)
           ^^^^^^^^^^^^^^^^^^^^^^^^^^^^^^^^^^^^^^^^^^^^^^^^^^^^
tests/test_core_app.py:13: in <module>
    from isa_superapp.core.app import ISASuperApp, create_app
E   ModuleNotFoundError: No module named 'isa_superapp'
_____________ ERROR collecting tests/test_geospatial_screening.py ______________
ImportError while importing test module '/Users/frisowempe/ISA_D/tests/test_geospatial_screening.py'.
Hint: make sure your test modules/packages have valid Python names.
Traceback:
/opt/homebrew/Cellar/python@3.13/3.13.7/Frameworks/Python.framework/Versions/3.13/lib/python3.13/importlib/__init__.py:88: in import_module
    return _bootstrap._gcd_import(name[level:], package, level)
           ^^^^^^^^^^^^^^^^^^^^^^^^^^^^^^^^^^^^^^^^^^^^^^^^^^^^
tests/test_geospatial_screening.py:11: in <module>
    from shapely.geometry import Point, Polygon
E   ModuleNotFoundError: No module named 'shapely'
_________________ ERROR collecting tests/test_llm_providers.py _________________
ImportError while importing test module '/Users/frisowempe/ISA_D/tests/test_llm_providers.py'.
Hint: make sure your test modules/packages have valid Python names.
Traceback:
/opt/homebrew/Cellar/python@3.13/3.13.7/Frameworks/Python.framework/Versions/3.13/lib/python3.13/importlib/__init__.py:88: in import_module
    return _bootstrap._gcd_import(name[level:], package, level)
           ^^^^^^^^^^^^^^^^^^^^^^^^^^^^^^^^^^^^^^^^^^^^^^^^^^^^
tests/test_llm_providers.py:11: in <module>
    from isa_superapp.core.exceptions import LLMError, LLMRateLimitError, LLMTimeoutError
E   ModuleNotFoundError: No module named 'isa_superapp'
_____________________ ERROR collecting tests/test_main.py ______________________
ImportError while importing test module '/Users/frisowempe/ISA_D/tests/test_main.py'.
Hint: make sure your test modules/packages have valid Python names.
Traceback:
/opt/homebrew/Cellar/python@3.13/3.13.7/Frameworks/Python.framework/Versions/3.13/lib/python3.13/importlib/__init__.py:88: in import_module
    return _bootstrap._gcd_import(name[level:], package, level)
           ^^^^^^^^^^^^^^^^^^^^^^^^^^^^^^^^^^^^^^^^^^^^^^^^^^^^
tests/test_main.py:13: in <module>
    from isa_superapp.core.config import Config
E   ModuleNotFoundError: No module named 'isa_superapp'
___________________ ERROR collecting tests/test_neo4j_gds.py ___________________
ImportError while importing test module '/Users/frisowempe/ISA_D/tests/test_neo4j_gds.py'.
Hint: make sure your test modules/packages have valid Python names.
Traceback:
/opt/homebrew/Cellar/python@3.13/3.13.7/Frameworks/Python.framework/Versions/3.13/lib/python3.13/importlib/__init__.py:88: in import_module
    return _bootstrap._gcd_import(name[level:], package, level)
           ^^^^^^^^^^^^^^^^^^^^^^^^^^^^^^^^^^^^^^^^^^^^^^^^^^^^
tests/test_neo4j_gds.py:25: in <module>
    from src.neo4j_gds_client import Neo4jGDSClient, Neo4jConfig, GDSConfig
src/neo4j_gds_client.py:22: in <module>
    from neo4j import GraphDatabase, Driver
E   ModuleNotFoundError: No module named 'neo4j'
___________________ ERROR collecting tests/test_retrieval.py ___________________
ImportError while importing test module '/Users/frisowempe/ISA_D/tests/test_retrieval.py'.
Hint: make sure your test modules/packages have valid Python names.
Traceback:
/opt/homebrew/Cellar/python@3.13/3.13.7/Frameworks/Python.framework/Versions/3.13/lib/python3.13/importlib/__init__.py:88: in import_module
    return _bootstrap._gcd_import(name[level:], package, level)
           ^^^^^^^^^^^^^^^^^^^^^^^^^^^^^^^^^^^^^^^^^^^^^^^^^^^^
tests/test_retrieval.py:12: in <module>
    from isa_superapp.core.exceptions import ConfigurationError, RetrievalError
E   ModuleNotFoundError: No module named 'isa_superapp'
___________________ ERROR collecting tests/test_vc_system.py ___________________
tests/test_vc_system.py:11: in <module>
    from src.supplier_attestation_vc import (
src/supplier_attestation_vc.py:44: in <module>
    @dataclass
     ^^^^^^^^^
/opt/homebrew/Cellar/python@3.13/3.13.7/Frameworks/Python.framework/Versions/3.13/lib/python3.13/dataclasses.py:1305: in dataclass
    return wrap(cls)
           ^^^^^^^^^
/opt/homebrew/Cellar/python@3.13/3.13.7/Frameworks/Python.framework/Versions/3.13/lib/python3.13/dataclasses.py:1295: in wrap
    return _process_class(cls, init, repr, eq, order, unsafe_hash,
/opt/homebrew/Cellar/python@3.13/3.13.7/Frameworks/Python.framework/Versions/3.13/lib/python3.13/dataclasses.py:1078: in _process_class
    _init_fn(all_init_fields,
/opt/homebrew/Cellar/python@3.13/3.13.7/Frameworks/Python.framework/Versions/3.13/lib/python3.13/dataclasses.py:627: in _init_fn
    raise TypeError(f'non-default argument {f.name!r} '
E   TypeError: non-default argument 'assessment_method' follows default argument 'valid_until'
_________________ ERROR collecting tests/test_vector_store.py __________________
ImportError while importing test module '/Users/frisowempe/ISA_D/tests/test_vector_store.py'.
Hint: make sure your test modules/packages have valid Python names.
Traceback:
/opt/homebrew/Cellar/python@3.13/3.13.7/Frameworks/Python.framework/Versions/3.13/lib/python3.13/importlib/__init__.py:88: in import_module
    return _bootstrap._gcd_import(name[level:], package, level)
           ^^^^^^^^^^^^^^^^^^^^^^^^^^^^^^^^^^^^^^^^^^^^^^^^^^^^
tests/test_vector_store.py:12: in <module>
    from isa_superapp.core.exceptions import ConfigurationError, VectorStoreError
E   ModuleNotFoundError: No module named 'isa_superapp'
_________________ ERROR collecting tests/test_vector_stores.py _________________
ImportError while importing test module '/Users/frisowempe/ISA_D/tests/test_vector_stores.py'.
Hint: make sure your test modules/packages have valid Python names.
Traceback:
/opt/homebrew/Cellar/python@3.13/3.13.7/Frameworks/Python.framework/Versions/3.13/lib/python3.13/importlib/__init__.py:88: in import_module
    return _bootstrap._gcd_import(name[level:], package, level)
           ^^^^^^^^^^^^^^^^^^^^^^^^^^^^^^^^^^^^^^^^^^^^^^^^^^^^
tests/test_vector_stores.py:11: in <module>
    from isa_superapp.core.exceptions import VectorStoreConnectionError, VectorStoreError
E   ModuleNotFoundError: No module named 'isa_superapp'
___________________ ERROR collecting tests/unit/test_llm.py ____________________
ImportError while importing test module '/Users/frisowempe/ISA_D/tests/unit/test_llm.py'.
Hint: make sure your test modules/packages have valid Python names.
Traceback:
/opt/homebrew/Cellar/python@3.13/3.13.7/Frameworks/Python.framework/Versions/3.13/lib/python3.13/importlib/__init__.py:88: in import_module
    return _bootstrap._gcd_import(name[level:], package, level)
           ^^^^^^^^^^^^^^^^^^^^^^^^^^^^^^^^^^^^^^^^^^^^^^^^^^^^
tests/unit/test_llm.py:14: in <module>
    from tests.utils import MockFactory, TestDataGenerator, TestValidators
tests/utils.py:23: in <module>
    from faker import Faker
E   ModuleNotFoundError: No module named 'faker'
__________________ ERROR collecting tests/unit/test_memory.py __________________
ImportError while importing test module '/Users/frisowempe/ISA_D/tests/unit/test_memory.py'.
Hint: make sure your test modules/packages have valid Python names.
Traceback:
/opt/homebrew/Cellar/python@3.13/3.13.7/Frameworks/Python.framework/Versions/3.13/lib/python3.13/importlib/__init__.py:88: in import_module
    return _bootstrap._gcd_import(name[level:], package, level)
           ^^^^^^^^^^^^^^^^^^^^^^^^^^^^^^^^^^^^^^^^^^^^^^^^^^^^
tests/unit/test_memory.py:15: in <module>
    from tests.utils import MockFactory, TestDataGenerator, TestValidators
tests/utils.py:23: in <module>
    from faker import Faker
E   ModuleNotFoundError: No module named 'faker'
________________ ERROR collecting tests/unit/test_retrieval.py _________________
ImportError while importing test module '/Users/frisowempe/ISA_D/tests/unit/test_retrieval.py'.
Hint: make sure your test modules/packages have valid Python names.
Traceback:
/opt/homebrew/Cellar/python@3.13/3.13.7/Frameworks/Python.framework/Versions/3.13/lib/python3.13/importlib/__init__.py:88: in import_module
    return _bootstrap._gcd_import(name[level:], package, level)
           ^^^^^^^^^^^^^^^^^^^^^^^^^^^^^^^^^^^^^^^^^^^^^^^^^^^^
tests/unit/test_retrieval.py:14: in <module>
    from tests.utils import MockFactory, TestDataGenerator, TestValidators
tests/utils.py:23: in <module>
    from faker import Faker
E   ModuleNotFoundError: No module named 'faker'
_______________ ERROR collecting tests/unit/test_vector_store.py _______________
ImportError while importing test module '/Users/frisowempe/ISA_D/tests/unit/test_vector_store.py'.
Hint: make sure your test modules/packages have valid Python names.
Traceback:
/opt/homebrew/Cellar/python@3.13/3.13.7/Frameworks/Python.framework/Versions/3.13/lib/python3.13/importlib/__init__.py:88: in import_module
    return _bootstrap._gcd_import(name[level:], package, level)
           ^^^^^^^^^^^^^^^^^^^^^^^^^^^^^^^^^^^^^^^^^^^^^^^^^^^^
tests/unit/test_vector_store.py:14: in <module>
    from tests.utils import MockFactory, TestDataGenerator, TestValidators
tests/utils.py:23: in <module>
    from faker import Faker
E   ModuleNotFoundError: No module named 'faker'
=============================== warnings summary ===============================
<frozen importlib._bootstrap>:488
<frozen importlib._bootstrap>:488
  <frozen importlib._bootstrap>:488: DeprecationWarning: builtin type SwigPyPacked has no __module__ attribute

<frozen importlib._bootstrap>:488
<frozen importlib._bootstrap>:488
  <frozen importlib._bootstrap>:488: DeprecationWarning: builtin type SwigPyObject has no __module__ attribute

<frozen importlib._bootstrap>:488
  <frozen importlib._bootstrap>:488: DeprecationWarning: builtin type swigvarlink has no __module__ attribute

src/audit_logger.py:91
  /Users/frisowempe/ISA_D/src/audit_logger.py:91: MovedIn20Warning: The ``declarative_base()`` function is now available as sqlalchemy.orm.declarative_base(). (deprecated since: 2.0) (Background on SQLAlchemy 2.0 at: https://sqlalche.me/e/b8d9)
    AuditBase = declarative_base()

src/agent_core/memory/rag_store.py:34
  /Users/frisowempe/ISA_D/src/agent_core/memory/rag_store.py:34: PydanticDeprecatedSince20: Pydantic V1 style `@validator` validators are deprecated. You should migrate to Pydantic V2 style `@field_validator` validators, see the migration guide for more details. Deprecated in Pydantic V2.0 to be removed in V3.0. See Pydantic V2 Migration Guide at https://errors.pydantic.dev/2.11/migration/
    @validator('checksum')

src/auth.py:38
  /Users/frisowempe/ISA_D/src/auth.py:38: MovedIn20Warning: The ``declarative_base()`` function is now available as sqlalchemy.orm.declarative_base(). (deprecated since: 2.0) (Background on SQLAlchemy 2.0 at: https://sqlalche.me/e/b8d9)
    Base = declarative_base()

src/taxonomy/models.py:15
  /Users/frisowempe/ISA_D/src/taxonomy/models.py:15: MovedIn20Warning: The ``declarative_base()`` function is now available as sqlalchemy.orm.declarative_base(). (deprecated since: 2.0) (Background on SQLAlchemy 2.0 at: https://sqlalche.me/e/b8d9)
    Base = declarative_base()

src/api_server.py:197
  /Users/frisowempe/ISA_D/src/api_server.py:197: DeprecationWarning: 
          on_event is deprecated, use lifespan event handlers instead.
  
          Read more about it in the
          [FastAPI docs for Lifespan Events](https://fastapi.tiangolo.com/advanced/events/).
          
    @app.on_event("startup")

.venv/lib/python3.13/site-packages/fastapi/applications.py:4495
  /Users/frisowempe/ISA_D/.venv/lib/python3.13/site-packages/fastapi/applications.py:4495: DeprecationWarning: 
          on_event is deprecated, use lifespan event handlers instead.
  
          Read more about it in the
          [FastAPI docs for Lifespan Events](https://fastapi.tiangolo.com/advanced/events/).
          
    return self.router.on_event(event_type)

-- Docs: https://docs.pytest.org/en/stable/how-to/capture-warnings.html
=========================== short test summary info ============================
ERROR tests/test_agents.py
ERROR tests/test_core.py
ERROR tests/test_core_app.py
ERROR tests/test_geospatial_screening.py
ERROR tests/test_llm_providers.py
ERROR tests/test_main.py
ERROR tests/test_neo4j_gds.py
ERROR tests/test_retrieval.py
ERROR tests/test_vc_system.py - TypeError: non-default argument 'assessment_m...
ERROR tests/test_vector_store.py
ERROR tests/test_vector_stores.py
ERROR tests/unit/test_llm.py
ERROR tests/unit/test_memory.py
ERROR tests/unit/test_retrieval.py
ERROR tests/unit/test_vector_store.py
!!!!!!!!!!!!!!!!!!! Interrupted: 15 errors during collection !!!!!!!!!!!!!!!!!!!
======================= 11 warnings, 15 errors in 10.22s =======================
<sys>:0: DeprecationWarning: builtin type swigvarlink has no __module__ attribute
Exit code: 0
